Workbook

Sheet INICIO
B2: EMCO LIMPIEZAS | G2: =HYPERLINK("https://docs.google.com/forms/d/1MWA_3QQuj04m0s62qD5rObx9A0THa2XVAx6CqyxaUEw/edit?usp=drive_web&ouid=113675598808100720363", " 📝 REGISTRAR NUEVA LIMPIEZA ") -> 📝 REGISTRAR NUEVA LIMPIEZA
B3: Panel de Control de Servicios
B5: 🚨 PENDIENTES | D5: ✅ AL DÍA | F5: 👥 TOTAL TAREAS
B6: =COUNTIFS('Consola de Gestión Emco V4'!E2:E1000, "<="&TODAY(), 'Consola de Gestión Emco V4'!E2:E1000, "<>") -> 25 | D6: =COUNTIF('Consola de Gestión Emco V4'!E2:E1000, ">"&TODAY()) -> 65 | F6: =COUNTA('Consola de Gestión Emco V4'!A2:A1000) -> 124
B9: 📅 AGENDA DE TRABAJO: URGENTES Y PARA HOY
B11: =IFERROR(__xludf.DUMMYFUNCTION("IFERROR(SORT(FILTER('Consola de Gestión Emco V4'!A2:E1000, ARRAYFORMULA(IFERROR('Consola de Gestión Emco V4'!E2:E1000 * 1, 99999)) <= TODAY()), 5, 1), ""🎉 ¡Todo al día..."")"),"Guillem de Anglesola, 3") -> Guillem de Anglesola, 3 | C11: =IFERROR(__xludf.DUMMYFUNCTION("""COMPUTED_VALUE"""),"Ventanas") -> Ventanas | D11: =IFERROR(__xludf.DUMMYFUNCTION("""COMPUTED_VALUE"""),1.0) -> 1 | E11: =IFERROR(__xludf.DUMMYFUNCTION("""COMPUTED_VALUE"""),45974.0) -> 45974 | F11: =IFERROR(__xludf.DUMMYFUNCTION("""COMPUTED_VALUE"""),46004.0) -> 46004
B12: =IFERROR(__xludf.DUMMYFUNCTION("""COMPUTED_VALUE"""),"Guillem de Anglesola, 3") -> Guillem de Anglesola, 3 | C12: =IFERROR(__xludf.DUMMYFUNCTION("""COMPUTED_VALUE"""),"Puerta") -> Puerta | D12: =IFERROR(__xludf.DUMMYFUNCTION("""COMPUTED_VALUE"""),1.0) -> 1 | E12: =IFERROR(__xludf.DUMMYFUNCTION("""COMPUTED_VALUE"""),45974.0) -> 45974 | F12: =IFERROR(__xludf.DUMMYFUNCTION("""COMPUTED_VALUE"""),46004.0) -> 46004
B13: =IFERROR(__xludf.DUMMYFUNCTION("""COMPUTED_VALUE"""),"Guillem de Anglesola, 3") -> Guillem de Anglesola, 3 | C13: =IFERROR(__xludf.DUMMYFUNCTION("""COMPUTED_VALUE"""),"Luminaria") -> Luminaria | D13: =IFERROR(__xludf.DUMMYFUNCTION("""COMPUTED_VALUE"""),3.0) -> 3 | E13: =IFERROR(__xludf.DUMMYFUNCTION("""COMPUTED_VALUE"""),45990.0) -> 45990 | F13: =IFERROR(__xludf.DUMMYFUNCTION("""COMPUTED_VALUE"""),46081.0) -> 46081
B14: =IFERROR(__xludf.DUMMYFUNCTION("""COMPUTED_VALUE"""),"Ausias March, 105") -> Ausias March, 105 | C14: =IFERROR(__xludf.DUMMYFUNCTION("""COMPUTED_VALUE"""),"Luminaria") -> Luminaria | D14: =IFERROR(__xludf.DUMMYFUNCTION("""COMPUTED_VALUE"""),1.0) -> 1 | E14: =IFERROR(__xludf.DUMMYFUNCTION("""COMPUTED_VALUE"""),46066.0) -> 46066 | F14: =IFERROR(__xludf.DUMMYFUNCTION("""COMPUTED_VALUE"""),46094.0) -> 46094
B15: =IFERROR(__xludf.DUMMYFUNCTION("""COMPUTED_VALUE"""),"Ausias March, 105") -> Ausias March, 105 | C15: =IFERROR(__xludf.DUMMYFUNCTION("""COMPUTED_VALUE"""),"Ventanas ") -> Ventanas | D15: =IFERROR(__xludf.DUMMYFUNCTION("""COMPUTED_VALUE"""),1.0) -> 1 | E15: =IFERROR(__xludf.DUMMYFUNCTION("""COMPUTED_VALUE"""),46067.0) -> 46067 | F15: =IFERROR(__xludf.DUMMYFUNCTION("""COMPUTED_VALUE"""),46095.0) -> 46095
B16: =IFERROR(__xludf.DUMMYFUNCTION("""COMPUTED_VALUE"""),"Ausias March, 105") -> Ausias March, 105 | C16: =IFERROR(__xludf.DUMMYFUNCTION("""COMPUTED_VALUE"""),"Puerta") -> Puerta | D16: =IFERROR(__xludf.DUMMYFUNCTION("""COMPUTED_VALUE"""),1.0) -> 1 | E16: =IFERROR(__xludf.DUMMYFUNCTION("""COMPUTED_VALUE"""),46067.0) -> 46067 | F16: =IFERROR(__xludf.DUMMYFUNCTION("""COMPUTED_VALUE"""),46095.0) -> 46095
B17: =IFERROR(__xludf.DUMMYFUNCTION("""COMPUTED_VALUE"""),"Ausias March, 105") -> Ausias March, 105 | C17: =IFERROR(__xludf.DUMMYFUNCTION("""COMPUTED_VALUE"""),"Terraza") -> Terraza | D17: =IFERROR(__xludf.DUMMYFUNCTION("""COMPUTED_VALUE"""),1.0) -> 1 | E17: =IFERROR(__xludf.DUMMYFUNCTION("""COMPUTED_VALUE"""),46068.0) -> 46068 | F17: =IFERROR(__xludf.DUMMYFUNCTION("""COMPUTED_VALUE"""),46096.0) -> 46096
B18: =IFERROR(__xludf.DUMMYFUNCTION("""COMPUTED_VALUE"""),"Linares, 21Bis") -> Linares, 21Bis | C18: =IFERROR(__xludf.DUMMYFUNCTION("""COMPUTED_VALUE"""),"Alicatado zaguán") -> Alicatado zaguán | D18: =IFERROR(__xludf.DUMMYFUNCTION("""COMPUTED_VALUE"""),1.0) -> 1 | E18: =IFERROR(__xludf.DUMMYFUNCTION("""COMPUTED_VALUE"""),46077.0) -> 46077 | F18: =IFERROR(__xludf.DUMMYFUNCTION("""COMPUTED_VALUE"""),46105.0) -> 46105
B19: =IFERROR(__xludf.DUMMYFUNCTION("""COMPUTED_VALUE"""),"AEPV") -> AEPV | C19: =IFERROR(__xludf.DUMMYFUNCTION("""COMPUTED_VALUE"""),"Ventanas") -> Ventanas | D19: =IFERROR(__xludf.DUMMYFUNCTION("""COMPUTED_VALUE"""),1.0) -> 1 | E19: =IFERROR(__xludf.DUMMYFUNCTION("""COMPUTED_VALUE"""),46080.0) -> 46080 | F19: =IFERROR(__xludf.DUMMYFUNCTION("""COMPUTED_VALUE"""),46108.0) -> 46108
B20: =IFERROR(__xludf.DUMMYFUNCTION("""COMPUTED_VALUE"""),"FEV") -> FEV | C20: =IFERROR(__xludf.DUMMYFUNCTION("""COMPUTED_VALUE"""),"Ventanas") -> Ventanas | D20: =IFERROR(__xludf.DUMMYFUNCTION("""COMPUTED_VALUE"""),1.0) -> 1 | E20: =IFERROR(__xludf.DUMMYFUNCTION("""COMPUTED_VALUE"""),46080.0) -> 46080 | F20: =IFERROR(__xludf.DUMMYFUNCTION("""COMPUTED_VALUE"""),46108.0) -> 46108
B21: =IFERROR(__xludf.DUMMYFUNCTION("""COMPUTED_VALUE"""),"Daroca, 26") -> Daroca, 26 | C21: =IFERROR(__xludf.DUMMYFUNCTION("""COMPUTED_VALUE"""),"Tejado") -> Tejado | D21: =IFERROR(__xludf.DUMMYFUNCTION("""COMPUTED_VALUE"""),1.0) -> 1 | E21: =IFERROR(__xludf.DUMMYFUNCTION("""COMPUTED_VALUE"""),46092.0) -> 46092 | F21: =IFERROR(__xludf.DUMMYFUNCTION("""COMPUTED_VALUE"""),46123.0) -> 46123
B22: =IFERROR(__xludf.DUMMYFUNCTION("""COMPUTED_VALUE"""),"Albacete, 21") -> Albacete, 21 | C22: =IFERROR(__xludf.DUMMYFUNCTION("""COMPUTED_VALUE"""),"Ventanas") -> Ventanas | D22: =IFERROR(__xludf.DUMMYFUNCTION("""COMPUTED_VALUE"""),1.0) -> 1 | E22: =IFERROR(__xludf.DUMMYFUNCTION("""COMPUTED_VALUE"""),46107.0) -> 46107 | F22: =IFERROR(__xludf.DUMMYFUNCTION("""COMPUTED_VALUE"""),46138.0) -> 46138
B23: =IFERROR(__xludf.DUMMYFUNCTION("""COMPUTED_VALUE"""),"Albacete, 21") -> Albacete, 21 | C23: =IFERROR(__xludf.DUMMYFUNCTION("""COMPUTED_VALUE"""),"Puerta") -> Puerta | D23: =IFERROR(__xludf.DUMMYFUNCTION("""COMPUTED_VALUE"""),1.0) -> 1 | E23: =IFERROR(__xludf.DUMMYFUNCTION("""COMPUTED_VALUE"""),46107.0) -> 46107 | F23: =IFERROR(__xludf.DUMMYFUNCTION("""COMPUTED_VALUE"""),46138.0) -> 46138
B24: =IFERROR(__xludf.DUMMYFUNCTION("""COMPUTED_VALUE"""),"VW Group Services") -> VW Group Services | C24: =IFERROR(__xludf.DUMMYFUNCTION("""COMPUTED_VALUE"""),"Ventanas") -> Ventanas | D24: =IFERROR(__xludf.DUMMYFUNCTION("""COMPUTED_VALUE"""),2.0) -> 2 | E24: =IFERROR(__xludf.DUMMYFUNCTION("""COMPUTED_VALUE"""),46080.0) -> 46080 | F24: =IFERROR(__xludf.DUMMYFUNCTION("""COMPUTED_VALUE"""),46139.0) -> 46139
B25: =IFERROR(__xludf.DUMMYFUNCTION("""COMPUTED_VALUE"""),"Mama Pottery") -> Mama Pottery | C25: =IFERROR(__xludf.DUMMYFUNCTION("""COMPUTED_VALUE"""),"Ventanas") -> Ventanas | D25: =IFERROR(__xludf.DUMMYFUNCTION("""COMPUTED_VALUE"""),0.5) -> 0.5 | E25: =IFERROR(__xludf.DUMMYFUNCTION("""COMPUTED_VALUE"""),46136.0) -> 46136 | F25: =IFERROR(__xludf.DUMMYFUNCTION("""COMPUTED_VALUE"""),46151.0) -> 46151
B26: =IFERROR(__xludf.DUMMYFUNCTION("""COMPUTED_VALUE"""),"Arquitecto Alfaro, 25") -> Arquitecto Alfaro, 25 | C26: =IFERROR(__xludf.DUMMYFUNCTION("""COMPUTED_VALUE"""),"Ventanas") -> Ventanas | D26: =IFERROR(__xludf.DUMMYFUNCTION("""COMPUTED_VALUE"""),2.0) -> 2 | E26: =IFERROR(__xludf.DUMMYFUNCTION("""COMPUTED_VALUE"""),46092.0) -> 46092 | F26: =IFERROR(__xludf.DUMMYFUNCTION("""COMPUTED_VALUE"""),46153.0) -> 46153
B27: =IFERROR(__xludf.DUMMYFUNCTION("""COMPUTED_VALUE"""),"Arquitecto Alfaro, 25") -> Arquitecto Alfaro, 25 | C27: =IFERROR(__xludf.DUMMYFUNCTION("""COMPUTED_VALUE"""),"Alicatado zaguán") -> Alicatado zaguán | D27: =IFERROR(__xludf.DUMMYFUNCTION("""COMPUTED_VALUE"""),2.0) -> 2 | E27: =IFERROR(__xludf.DUMMYFUNCTION("""COMPUTED_VALUE"""),46092.0) -> 46092 | F27: =IFERROR(__xludf.DUMMYFUNCTION("""COMPUTED_VALUE"""),46153.0) -> 46153
B28: =IFERROR(__xludf.DUMMYFUNCTION("""COMPUTED_VALUE"""),"San Cristóbal, 8") -> San Cristóbal, 8 | C28: =IFERROR(__xludf.DUMMYFUNCTION("""COMPUTED_VALUE"""),"Ventanas") -> Ventanas | D28: =IFERROR(__xludf.DUMMYFUNCTION("""COMPUTED_VALUE"""),2.0) -> 2 | E28: =IFERROR(__xludf.DUMMYFUNCTION("""COMPUTED_VALUE"""),46092.0) -> 46092 | F28: =IFERROR(__xludf.DUMMYFUNCTION("""COMPUTED_VALUE"""),46153.0) -> 46153
B29: =IFERROR(__xludf.DUMMYFUNCTION("""COMPUTED_VALUE"""),"San Cristóbal, 8") -> San Cristóbal, 8 | C29: =IFERROR(__xludf.DUMMYFUNCTION("""COMPUTED_VALUE"""),"Puerta") -> Puerta | D29: =IFERROR(__xludf.DUMMYFUNCTION("""COMPUTED_VALUE"""),2.0) -> 2 | E29: =IFERROR(__xludf.DUMMYFUNCTION("""COMPUTED_VALUE"""),46092.0) -> 46092 | F29: =IFERROR(__xludf.DUMMYFUNCTION("""COMPUTED_VALUE"""),46153.0) -> 46153
B30: =IFERROR(__xludf.DUMMYFUNCTION("""COMPUTED_VALUE"""),"San Cristóbal, 8") -> San Cristóbal, 8 | C30: =IFERROR(__xludf.DUMMYFUNCTION("""COMPUTED_VALUE"""),"Alicatado zaguán") -> Alicatado zaguán | D30: =IFERROR(__xludf.DUMMYFUNCTION("""COMPUTED_VALUE"""),2.0) -> 2 | E30: =IFERROR(__xludf.DUMMYFUNCTION("""COMPUTED_VALUE"""),46092.0) -> 46092 | F30: =IFERROR(__xludf.DUMMYFUNCTION("""COMPUTED_VALUE"""),46153.0) -> 46153
B31: =IFERROR(__xludf.DUMMYFUNCTION("""COMPUTED_VALUE"""),"Virgen del Puig, 20") -> Virgen del Puig, 20 | C31: =IFERROR(__xludf.DUMMYFUNCTION("""COMPUTED_VALUE"""),"Ventanas") -> Ventanas | D31: =IFERROR(__xludf.DUMMYFUNCTION("""COMPUTED_VALUE"""),2.0) -> 2 | E31: =IFERROR(__xludf.DUMMYFUNCTION("""COMPUTED_VALUE"""),46092.0) -> 46092 | F31: =IFERROR(__xludf.DUMMYFUNCTION("""COMPUTED_VALUE"""),46153.0) -> 46153
B32: =IFERROR(__xludf.DUMMYFUNCTION("""COMPUTED_VALUE"""),"Virgen del Puig, 20") -> Virgen del Puig, 20 | C32: =IFERROR(__xludf.DUMMYFUNCTION("""COMPUTED_VALUE"""),"Puerta") -> Puerta | D32: =IFERROR(__xludf.DUMMYFUNCTION("""COMPUTED_VALUE"""),2.0) -> 2 | E32: =IFERROR(__xludf.DUMMYFUNCTION("""COMPUTED_VALUE"""),46092.0) -> 46092 | F32: =IFERROR(__xludf.DUMMYFUNCTION("""COMPUTED_VALUE"""),46153.0) -> 46153
B33: =IFERROR(__xludf.DUMMYFUNCTION("""COMPUTED_VALUE"""),"Bernia, 9") -> Bernia, 9 | C33: =IFERROR(__xludf.DUMMYFUNCTION("""COMPUTED_VALUE"""),"Ventanas") -> Ventanas | D33: =IFERROR(__xludf.DUMMYFUNCTION("""COMPUTED_VALUE"""),3.0) -> 3 | E33: =IFERROR(__xludf.DUMMYFUNCTION("""COMPUTED_VALUE"""),46066.0) -> 46066 | F33: =IFERROR(__xludf.DUMMYFUNCTION("""COMPUTED_VALUE"""),46155.0) -> 46155
B34: =IFERROR(__xludf.DUMMYFUNCTION("""COMPUTED_VALUE"""),"Bernia, 9") -> Bernia, 9 | C34: =IFERROR(__xludf.DUMMYFUNCTION("""COMPUTED_VALUE"""),"Puerta") -> Puerta | D34: =IFERROR(__xludf.DUMMYFUNCTION("""COMPUTED_VALUE"""),3.0) -> 3 | E34: =IFERROR(__xludf.DUMMYFUNCTION("""COMPUTED_VALUE"""),46066.0) -> 46066 | F34: =IFERROR(__xludf.DUMMYFUNCTION("""COMPUTED_VALUE"""),46155.0) -> 46155
B35: =IFERROR(__xludf.DUMMYFUNCTION("""COMPUTED_VALUE"""),"Guillem de Anglesola, 3") -> Guillem de Anglesola, 3 | C35: =IFERROR(__xludf.DUMMYFUNCTION("""COMPUTED_VALUE"""),"Terraza") -> Terraza | D35: =IFERROR(__xludf.DUMMYFUNCTION("""COMPUTED_VALUE"""),6.0) -> 6 | E35: =IFERROR(__xludf.DUMMYFUNCTION("""COMPUTED_VALUE"""),45974.0) -> 45974 | F35: =IFERROR(__xludf.DUMMYFUNCTION("""COMPUTED_VALUE"""),46155.0) -> 46155
B36: =IFERROR(__xludf.DUMMYFUNCTION("""COMPUTED_VALUE"""),"Arquitecto Alfaro, 25") -> Arquitecto Alfaro, 25 | C36: =IFERROR(__xludf.DUMMYFUNCTION("""COMPUTED_VALUE""")," Puerta") -> Puerta | D36: =IFERROR(__xludf.DUMMYFUNCTION("""COMPUTED_VALUE"""),1.0) -> 1 | E36: =IFERROR(__xludf.DUMMYFUNCTION("""COMPUTED_VALUE"""),"") | F36: =IFERROR(__xludf.DUMMYFUNCTION("""COMPUTED_VALUE"""),"")
B37: =IFERROR(__xludf.DUMMYFUNCTION("""COMPUTED_VALUE"""),"Camino Alabau, 20") -> Camino Alabau, 20 | C37: =IFERROR(__xludf.DUMMYFUNCTION("""COMPUTED_VALUE"""),"Ventanas") -> Ventanas | D37: =IFERROR(__xludf.DUMMYFUNCTION("""COMPUTED_VALUE"""),1.0) -> 1 | F37: =IFERROR(__xludf.DUMMYFUNCTION("""COMPUTED_VALUE"""),"")
B38: =IFERROR(__xludf.DUMMYFUNCTION("""COMPUTED_VALUE"""),"Camino Alabau, 20") -> Camino Alabau, 20 | C38: =IFERROR(__xludf.DUMMYFUNCTION("""COMPUTED_VALUE"""),"Puerta") -> Puerta | D38: =IFERROR(__xludf.DUMMYFUNCTION("""COMPUTED_VALUE"""),1.0) -> 1 | F38: =IFERROR(__xludf.DUMMYFUNCTION("""COMPUTED_VALUE"""),"")
B39: =IFERROR(__xludf.DUMMYFUNCTION("""COMPUTED_VALUE"""),"Camino Alabau, 20") -> Camino Alabau, 20 | C39: =IFERROR(__xludf.DUMMYFUNCTION("""COMPUTED_VALUE"""),"Alicatado zaguán") -> Alicatado zaguán | D39: =IFERROR(__xludf.DUMMYFUNCTION("""COMPUTED_VALUE"""),1.0) -> 1 | F39: =IFERROR(__xludf.DUMMYFUNCTION("""COMPUTED_VALUE"""),"")
B40: =IFERROR(__xludf.DUMMYFUNCTION("""COMPUTED_VALUE"""),"Camino Alabau, 20") -> Camino Alabau, 20 | C40: =IFERROR(__xludf.DUMMYFUNCTION("""COMPUTED_VALUE"""),"Luminaria") -> Luminaria | D40: =IFERROR(__xludf.DUMMYFUNCTION("""COMPUTED_VALUE"""),1.0) -> 1 | F40: =IFERROR(__xludf.DUMMYFUNCTION("""COMPUTED_VALUE"""),"")
B41: =IFERROR(__xludf.DUMMYFUNCTION("""COMPUTED_VALUE"""),"Camino Alabau, 20") -> Camino Alabau, 20 | C41: =IFERROR(__xludf.DUMMYFUNCTION("""COMPUTED_VALUE"""),"Terraza") -> Terraza | D41: =IFERROR(__xludf.DUMMYFUNCTION("""COMPUTED_VALUE"""),1.0) -> 1 | F41: =IFERROR(__xludf.DUMMYFUNCTION("""COMPUTED_VALUE"""),"")
B42: =IFERROR(__xludf.DUMMYFUNCTION("""COMPUTED_VALUE"""),"Camino Alabau, 20") -> Camino Alabau, 20 | C42: =IFERROR(__xludf.DUMMYFUNCTION("""COMPUTED_VALUE"""),"Cuartos") -> Cuartos | D42: =IFERROR(__xludf.DUMMYFUNCTION("""COMPUTED_VALUE"""),1.0) -> 1 | F42: =IFERROR(__xludf.DUMMYFUNCTION("""COMPUTED_VALUE"""),"")
B43: =IFERROR(__xludf.DUMMYFUNCTION("""COMPUTED_VALUE"""),"Camino Alabau, 24") -> Camino Alabau, 24 | C43: =IFERROR(__xludf.DUMMYFUNCTION("""COMPUTED_VALUE"""),"Ventanas") -> Ventanas | D43: =IFERROR(__xludf.DUMMYFUNCTION("""COMPUTED_VALUE"""),1.0) -> 1 | F43: =IFERROR(__xludf.DUMMYFUNCTION("""COMPUTED_VALUE"""),"")
B44: =IFERROR(__xludf.DUMMYFUNCTION("""COMPUTED_VALUE"""),"Camino Alabau, 24") -> Camino Alabau, 24 | C44: =IFERROR(__xludf.DUMMYFUNCTION("""COMPUTED_VALUE"""),"Puerta") -> Puerta | D44: =IFERROR(__xludf.DUMMYFUNCTION("""COMPUTED_VALUE"""),1.0) -> 1 | F44: =IFERROR(__xludf.DUMMYFUNCTION("""COMPUTED_VALUE"""),"")
B45: =IFERROR(__xludf.DUMMYFUNCTION("""COMPUTED_VALUE"""),"Camino Alabau, 24") -> Camino Alabau, 24 | C45: =IFERROR(__xludf.DUMMYFUNCTION("""COMPUTED_VALUE"""),"Luminaria") -> Luminaria | D45: =IFERROR(__xludf.DUMMYFUNCTION("""COMPUTED_VALUE"""),1.0) -> 1 | F45: =IFERROR(__xludf.DUMMYFUNCTION("""COMPUTED_VALUE"""),"")
...

Sheet Consola de Gestión Emco V4
A1: Cliente | B1: Servicio | C1: Frecuencia (Meses) | D1: Ultima Fecha | E1: Proxima Fecha Estimada | F1: Tipo de Inmueble | G1: Observaciones
A2: Albacete, 21 | B2: Ventanas | C2: 1 | D2: 46107 | E2: =IF(D2="", "", IF(MOD(C2, 1)=0, EDATE(D2, C2), D2 + (C2 * 30))) -> 46138 | F2: Comunidad
A3: Albacete, 21 | B3: Puerta | C3: 1 | D3: 46107 | E3: =IF(D3="", "", IF(MOD(C3, 1)=0, EDATE(D3, C3), D3 + (C3 * 30))) -> 46138 | F3: Comunidad
A4: Albacete, 21 | B4: Alicatado zaguán | C4: 2 | D4: 46107 | E4: =IF(D4="", "", IF(MOD(C4, 1)=0, EDATE(D4, C4), D4 + (C4 * 30))) -> 46168 | F4: Comunidad
A5: Albacete, 21 | B5: Luminaria | C5: 2 | D5: 46107 | E5: =IF(D5="", "", IF(MOD(C5, 1)=0, EDATE(D5, C5), D5 + (C5 * 30))) -> 46168 | F5: Comunidad
A6: Albacete, 21 | B6: Terraza | C6: 2 | D6: 46107 | E6: =IF(D6="", "", IF(MOD(C6, 1)=0, EDATE(D6, C6), D6 + (C6 * 30))) -> 46168 | F6: Comunidad
A7: Albacete, 21 | B7: Cuartos | C7: 6 | D7: 46107 | E7: =IF(D7="", "", IF(MOD(C7, 1)=0, EDATE(D7, C7), D7 + (C7 * 30))) -> 46291 | F7: Comunidad
A8: Alboraya, 10 | B8: Ventanas | C8: 1 | D8: =IF(MAXIFS('Respuestas de formulario 1'!$D:$D, 'Respuestas de formulario 1'!$B:$B, "*"&A8&"*", 'Respuestas de formulario 1'!$C:$C, "*"&B8&"*")=0, "", MAXIFS('Respuestas de formulario 1'!$D:$D, 'Respuestas de formulario 1'!$B:$B, "*"&A8&"*", 'Respuestas de formulario 1'!$C:$C, "*"&B8&"*")) -> 46140 | E8: =IF(D8="", "", IF(MOD(C8, 1)=0, EDATE(D8, C8), D8 + (C8 * 30))) -> 46170 | F8: Comunidad
A9: Alboraya, 10 | B9: Puerta | C9: 1 | D9: =IF(MAXIFS('Respuestas de formulario 1'!$D:$D, 'Respuestas de formulario 1'!$B:$B, "*"&A9&"*", 'Respuestas de formulario 1'!$C:$C, "*"&B9&"*")=0, "", MAXIFS('Respuestas de formulario 1'!$D:$D, 'Respuestas de formulario 1'!$B:$B, "*"&A9&"*", 'Respuestas de formulario 1'!$C:$C, "*"&B9&"*")) -> 46140 | E9: =IF(D9="", "", IF(MOD(C9, 1)=0, EDATE(D9, C9), D9 + (C9 * 30))) -> 46170 | F9: Comunidad
A10: Alboraya, 10 | B10: Luminaria | C10: 1 | D10: =IF(MAXIFS('Respuestas de formulario 1'!$D:$D, 'Respuestas de formulario 1'!$B:$B, "*"&A10&"*", 'Respuestas de formulario 1'!$C:$C, "*"&B10&"*")=0, "", MAXIFS('Respuestas de formulario 1'!$D:$D, 'Respuestas de formulario 1'!$B:$B, "*"&A10&"*", 'Respuestas de formulario 1'!$C:$C, "*"&B10&"*")) -> 46140 | E10: =IF(D10="", "", IF(MOD(C10, 1)=0, EDATE(D10, C10), D10 + (C10 * 30))) -> 46170 | F10: Comunidad
A11: Alboraya, 10 | B11: Terraza | C11: 6 | D11: =IF(MAXIFS('Respuestas de formulario 1'!$D:$D, 'Respuestas de formulario 1'!$B:$B, "*"&A11&"*", 'Respuestas de formulario 1'!$C:$C, "*"&B11&"*")=0, "", MAXIFS('Respuestas de formulario 1'!$D:$D, 'Respuestas de formulario 1'!$B:$B, "*"&A11&"*", 'Respuestas de formulario 1'!$C:$C, "*"&B11&"*")) -> 46085 | E11: =IF(D11="", "", IF(MOD(C11, 1)=0, EDATE(D11, C11), D11 + (C11 * 30))) -> 46269 | F11: Comunidad
A12: Arquitecto Alfaro, 25 | B12: Pasaje | C12: 1 | D12: =IF(MAXIFS('Respuestas de formulario 1'!$D:$D, 'Respuestas de formulario 1'!$B:$B, "*"&A12&"*", 'Respuestas de formulario 1'!$C:$C, "*"&B12&"*")=0, "", MAXIFS('Respuestas de formulario 1'!$D:$D, 'Respuestas de formulario 1'!$B:$B, "*"&A12&"*", 'Respuestas de formulario 1'!$C:$C, "*"&B12&"*")) -> 46144 | E12: =IF(D12="", "", IF(MOD(C12, 1)=0, EDATE(D12, C12), D12 + (C12 * 30))) -> 46175 | F12: Comunidad
A13: Arquitecto Alfaro, 25 | B13: Puerta | C13: 1 | D13: =IF(MAXIFS('Respuestas de formulario 1'!$D:$D, 'Respuestas de formulario 1'!$B:$B, "*"&A13&"*", 'Respuestas de formulario 1'!$C:$C, "*"&B13&"*")=0, "", MAXIFS('Respuestas de formulario 1'!$D:$D, 'Respuestas de formulario 1'!$B:$B, "*"&A13&"*", 'Respuestas de formulario 1'!$C:$C, "*"&B13&"*")) | E13: =IF(D13="", "", IF(MOD(C13, 1)=0, EDATE(D13, C13), D13 + (C13 * 30)))
A14: Arquitecto Alfaro, 25 | B14: Ventanas | C14: 2 | D14: 46092 | E14: =IF(D14="", "", IF(MOD(C14, 1)=0, EDATE(D14, C14), D14 + (C14 * 30))) -> 46153 | F14: Comunidad
A15: Arquitecto Alfaro, 25 | B15: Luminaria | C15: 3 | D15: 46092 | E15: =IF(D15="", "", IF(MOD(C15, 1)=0, EDATE(D15, C15), D15 + (C15 * 30))) -> 46184 | F15: Comunidad
A16: Arquitecto Alfaro, 25 | B16: Cuartos | C16: 6 | D16: 46092 | E16: =IF(D16="", "", IF(MOD(C16, 1)=0, EDATE(D16, C16), D16 + (C16 * 30))) -> 46276 | F16: Comunidad
A17: Arquitecto Alfaro, 25 | B17: Alicatado zaguán | C17: 2 | D17: 46092 | E17: =IF(D17="", "", IF(MOD(C17, 1)=0, EDATE(D17, C17), D17 + (C17 * 30))) -> 46153 | F17: Comunidad
A18: Ausias March, 105 | B18: Luminaria | C18: 1 | D18: 46066 | E18: =IF(D18="", "", IF(MOD(C18, 1)=0, EDATE(D18, C18), D18 + (C18 * 30))) -> 46094 | F18: Comunidad
A19: Ausias March, 105 | B19: Ventanas | C19: 1 | D19: 46067 | E19: =IF(D19="", "", IF(MOD(C19, 1)=0, EDATE(D19, C19), D19 + (C19 * 30))) -> 46095
A20: Ausias March, 105 | B20: Puerta | C20: 1 | D20: 46067 | E20: =IF(D20="", "", IF(MOD(C20, 1)=0, EDATE(D20, C20), D20 + (C20 * 30))) -> 46095 | F20: Comunidad
A21: Ausias March, 105 | B21: Terraza | C21: 1 | D21: 46068 | E21: =IF(D21="", "", IF(MOD(C21, 1)=0, EDATE(D21, C21), D21 + (C21 * 30))) -> 46096 | F21: Comunidad
A22: Baja, 42 | B22: Terraza | C22: 6 | D22: 45990 | E22: =IF(D22="", "", IF(MOD(C22, 1)=0, EDATE(D22, C22), D22 + (C22 * 30))) -> 46171 | F22: Comunidad
A23: Baja, 42 | B23: Vitrificado | C23: 12 | D23: 45990 | E23: =IF(D23="", "", IF(MOD(C23, 1)=0, EDATE(D23, C23), D23 + (C23 * 30))) -> 46355 | F23: Comunidad
A24: Bellús, 1 | B24: Ventanas | C24: 1 | D24: =IF(MAXIFS('Respuestas de formulario 1'!$D:$D, 'Respuestas de formulario 1'!$B:$B, "*"&A24&"*", 'Respuestas de formulario 1'!$C:$C, "*"&B24&"*")=0, "", MAXIFS('Respuestas de formulario 1'!$D:$D, 'Respuestas de formulario 1'!$B:$B, "*"&A24&"*", 'Respuestas de formulario 1'!$C:$C, "*"&B24&"*")) -> 46140 | E24: =IF(D24="", "", IF(MOD(C24, 1)=0, EDATE(D24, C24), D24 + (C24 * 30))) -> 46170 | F24: Comunidad
A25: Bellús, 1 | B25: Puerta | C25: 1 | D25: =IF(MAXIFS('Respuestas de formulario 1'!$D:$D, 'Respuestas de formulario 1'!$B:$B, "*"&A25&"*", 'Respuestas de formulario 1'!$C:$C, "*"&B25&"*")=0, "", MAXIFS('Respuestas de formulario 1'!$D:$D, 'Respuestas de formulario 1'!$B:$B, "*"&A25&"*", 'Respuestas de formulario 1'!$C:$C, "*"&B25&"*")) -> 46140 | E25: =IF(D25="", "", IF(MOD(C25, 1)=0, EDATE(D25, C25), D25 + (C25 * 30))) -> 46170 | F25: Comunidad
A26: Bellús, 1 | B26: Luminaria | C26: 1 | D26: 46140 | E26: =IF(D26="", "", IF(MOD(C26, 1)=0, EDATE(D26, C26), D26 + (C26 * 30))) -> 46170 | F26: Comunidad
A27: Bernia, 9 | B27: Ventanas | C27: 3 | D27: 46066 | E27: =IF(D27="", "", IF(MOD(C27, 1)=0, EDATE(D27, C27), D27 + (C27 * 30))) -> 46155 | F27: Comunidad
A28: Bernia, 9 | B28: Puerta | C28: 3 | D28: 46066 | E28: =IF(D28="", "", IF(MOD(C28, 1)=0, EDATE(D28, C28), D28 + (C28 * 30))) -> 46155 | F28: Comunidad
A29: Bernia, 9 | B29: Vitrificado | C29: 12 | D29: 46354 | E29: =IF(D29="", "", IF(MOD(C29, 1)=0, EDATE(D29, C29), D29 + (C29 * 30))) -> 46719 | F29: Comunidad
A30: Camino Alabau, 20 | B30: Ventanas | C30: 1 | E30: =IF(D30="", "", IF(MOD(C30, 1)=0, EDATE(D30, C30), D30 + (C30 * 30))) | F30: Comunidad
A31: Camino Alabau, 20 | B31: Puerta | C31: 1 | E31: =IF(D31="", "", IF(MOD(C31, 1)=0, EDATE(D31, C31), D31 + (C31 * 30))) | F31: Comunidad
A32: Camino Alabau, 20 | B32: Alicatado zaguán | C32: 1 | E32: =IF(D32="", "", IF(MOD(C32, 1)=0, EDATE(D32, C32), D32 + (C32 * 30))) | F32: Comunidad
A33: Camino Alabau, 20 | B33: Luminaria | C33: 1 | E33: =IF(D33="", "", IF(MOD(C33, 1)=0, EDATE(D33, C33), D33 + (C33 * 30))) | F33: Comunidad
A34: Camino Alabau, 20 | B34: Terraza | C34: 1 | E34: =IF(D34="", "", IF(MOD(C34, 1)=0, EDATE(D34, C34), D34 + (C34 * 30))) | F34: Comunidad
A35: Camino Alabau, 20 | B35: Cuartos | C35: 1 | E35: =IF(D35="", "", IF(MOD(C35, 1)=0, EDATE(D35, C35), D35 + (C35 * 30))) | F35: Comunidad
A36: Camino Alabau, 24 | B36: Ventanas | C36: 1 | E36: =IF(D36="", "", IF(MOD(C36, 1)=0, EDATE(D36, C36), D36 + (C36 * 30))) | F36: Comunidad
A37: Camino Alabau, 24 | B37: Puerta | C37: 1 | E37: =IF(D37="", "", IF(MOD(C37, 1)=0, EDATE(D37, C37), D37 + (C37 * 30))) | F37: Comunidad
A38: Camino Alabau, 24 | B38: Luminaria | C38: 1 | E38: =IF(D38="", "", IF(MOD(C38, 1)=0, EDATE(D38, C38), D38 + (C38 * 30))) | F38: Comunidad
A39: Camino Alabau, 24 | B39: Terraza | C39: 1 | E39: =IF(D39="", "", IF(MOD(C39, 1)=0, EDATE(D39, C39), D39 + (C39 * 30))) | F39: Comunidad
A40: Camino Alabau, 24 | B40: Cuartos | C40: 1 | E40: =IF(D40="", "", IF(MOD(C40, 1)=0, EDATE(D40, C40), D40 + (C40 * 30))) | F40: Comunidad
...

Sheet Respuestas de formulario 1
A1: Marca temporal | B1: Cliente | C1: Servicio Realizado | D1: Fecha del Servicio | E1: Notas / Observaciones | F1: Operario | G1: Selecciona el Cliente | H1: Servicios realizados en AEPV | I1: Servicios realizados en Albacete, 21 | J1: Servicios realizados en Alboraya, 10 | K1: Servicios realizados en Arquitecto Alfaro, 25 | L1: Servicios realizados en Ausias March, 105 | M1: Servicios realizados en Baja, 42 | N1: Servicios realizados en Bellús, 1 | O1: Servicios realizados en Bernia, 9 | P1: Servicios realizados en Camino Alabau, 20 | Q1: Servicios realizados en Camino Alabau, 24 | R1: Servicios realizados en Camino Alabau, 8 | S1: Servicios realizados en Centro Estética Avanzada Amparo Sánchez | T1: Servicios realizados en DaaS Group | U1: Servicios realizados en Daroca, 26 | V1: Servicios realizados en Duque de Calabria, 3 | W1: Servicios realizados en EOLAB | X1: Servicios realizados en Escrivá, 2 | Y1: Servicios realizados en FEV | Z1: Servicios realizados en Fuencaliente, 8 | AA1: Servicios realizados en Guillem de Anglesola, 3 | AB1: Servicios realizados en Linares, 21Bis | AC1: Servicios realizados en Madersan | AD1: Servicios realizados en Mama Pottery | AE1: Servicios realizados en Músico Cabanilles, 42 | AF1: Servicios realizados en PDBF, 1 | AG1: Servicios realizados en PDBF, 2 | AH1: Servicios realizados en Pintor Genaro Lahuerta, 45 | AI1: Servicios realizados en Plaza Dramaturgo Fausto Hernández Casajuana, 2 | AJ1: Servicios realizados en San Cristóbal, 8 | AK1: Servicios realizados en Scito Fundació | AL1: Servicios realizados en Studio Pilates Adela Ferrer | AM1: Servicios realizados en VW Group Services | AN1: Servicios realizados en Victor Barbeta - Arquitecto | AO1: Servicios realizados en Virgen del Puig, 20
A2: 46142.428 | B2: Alboraya, 10 | C2: Ventanas, Puerta Patio, Terraza, Alicatado zaguán | D2: 46085 | F2: Ivan
A3: 46142.393 | B3: Alboraya, 10 | C3: Ventanas, Puerta Patio, Alicatado zaguán, Luminaria | D3: 46140 | F3: Ivan
A4: 46142.393 | B4: Bellús, 1 | C4: Ventanas, Puerta Patio, Alicatado zaguán | D4: 46140 | F4: Ivan
A5: 46142.394 | B5: Daroca, 26 | C5: Ventanas, Puerta Patio, Terraza, Alicatado zaguán | D5: 46140 | F5: Ivan
A6: 46142.394 | B6: Músico Cabanilles, 42 | C6: Ventanas, Puerta Patio, Terraza, Alicatado zaguán | D6: 46140 | F6: Ivan
A7: 46142.396 | B7: PDBF, 1 | C7: Ventanas, Puerta Patio, Terraza, Alicatado zaguán, Luminaria | D7: 46140 | F7: Ivan
A8: 46142.396 | B8: PDBF, 2 | C8: Ventanas, Puerta Patio, Terraza, Alicatado zaguán | D8: 46140 | F8: Ivan
A9: 46142.393 | B9: Pintor Genaro Lahuerta, 45 | C9: Ventanas, Puerta Patio, Alicatado zaguán | D9: 46140 | F9: Ivan
A10: 46142.396 | B10: Plaza Dramaturgo Fausto Hernández Casajuana, 2 | C10: Puerta Patio | D10: 46140 | F10: Ivan
A11: 46142.448 | B11: Alboraya, 10 | C11: Ventanas, Puerta Patio, Alicatado zaguán | D11: 46044 | F11: Ivan
A12: 46142.45 | B12: Bellús, 1 | C12: Ventanas, Puerta Patio, Alicatado zaguán | D12: 46092 | F12: Ivan
A13: 46144.832 | B13: Arquitecto Alfaro, 25 | C13: Pasaje | D13: 46144
A14: 46145.445 | B14: PDBF, 2 | C14: Ventanas, Puerta Patio | D14: 46145
A15: 46162.635 | B15: VW Group Services | C15: Ventanas | D15: 46162
A16: 46162.716 | B16: AEPV | C16: Ventanas | D16: 46162
A17: 46162.77 | B17: FEV | C17: Cristales | D17: 46162
A18: 46162.771 | B18: FEV | C18: Ventanas | D18: 46162

Sheet HISTORIAL LIMPIO
A1: =IFERROR(__xludf.DUMMYFUNCTION("{ 'Respuestas de formulario 1'!A1:F1 ; SORT(FILTER('Respuestas de formulario 1'!A2:F1000, ('Respuestas de formulario 1'!D2:D1000 <= TODAY()) * ('Respuestas de formulario 1'!D2:D1000 <> """")), 2, 1, 4, 1) }"),"Marca temporal") -> Marca temporal | B1: =IFERROR(__xludf.DUMMYFUNCTION("""COMPUTED_VALUE"""),"Cliente") -> Cliente | C1: =IFERROR(__xludf.DUMMYFUNCTION("""COMPUTED_VALUE"""),"Servicio Realizado") -> Servicio Realizado | D1: =IFERROR(__xludf.DUMMYFUNCTION("""COMPUTED_VALUE"""),"Fecha del Servicio") -> Fecha del Servicio | E1: =IFERROR(__xludf.DUMMYFUNCTION("""COMPUTED_VALUE"""),"Notas / Observaciones") -> Notas / Observaciones | F1: =IFERROR(__xludf.DUMMYFUNCTION("""COMPUTED_VALUE"""),"Operario") -> Operario
A2: =IFERROR(__xludf.DUMMYFUNCTION("""COMPUTED_VALUE"""),46162.71590137732) -> 46162.716 | B2: =IFERROR(__xludf.DUMMYFUNCTION("""COMPUTED_VALUE"""),"AEPV") -> AEPV | C2: =IFERROR(__xludf.DUMMYFUNCTION("""COMPUTED_VALUE"""),"Ventanas") -> Ventanas | D2: =IFERROR(__xludf.DUMMYFUNCTION("""COMPUTED_VALUE"""),46162.0) -> 46162
A3: =IFERROR(__xludf.DUMMYFUNCTION("""COMPUTED_VALUE"""),46142.447930208335) -> 46142.448 | B3: =IFERROR(__xludf.DUMMYFUNCTION("""COMPUTED_VALUE"""),"Alboraya, 10") -> Alboraya, 10 | C3: =IFERROR(__xludf.DUMMYFUNCTION("""COMPUTED_VALUE"""),"Ventanas, Puerta Patio, Alicatado zaguán") -> Ventanas, Puerta Patio, Alicatado zaguán | D3: =IFERROR(__xludf.DUMMYFUNCTION("""COMPUTED_VALUE"""),46044.0) -> 46044 | F3: =IFERROR(__xludf.DUMMYFUNCTION("""COMPUTED_VALUE"""),"Ivan") -> Ivan
A4: =IFERROR(__xludf.DUMMYFUNCTION("""COMPUTED_VALUE"""),46142.42804197917) -> 46142.428 | B4: =IFERROR(__xludf.DUMMYFUNCTION("""COMPUTED_VALUE"""),"Alboraya, 10") -> Alboraya, 10 | C4: =IFERROR(__xludf.DUMMYFUNCTION("""COMPUTED_VALUE"""),"Ventanas, Puerta Patio, Terraza, Alicatado zaguán") -> Ventanas, Puerta Patio, Terraza, Alicatado zaguán | D4: =IFERROR(__xludf.DUMMYFUNCTION("""COMPUTED_VALUE"""),46085.0) -> 46085 | F4: =IFERROR(__xludf.DUMMYFUNCTION("""COMPUTED_VALUE"""),"Ivan") -> Ivan
A5: =IFERROR(__xludf.DUMMYFUNCTION("""COMPUTED_VALUE"""),46142.3925819213) -> 46142.393 | B5: =IFERROR(__xludf.DUMMYFUNCTION("""COMPUTED_VALUE"""),"Alboraya, 10") -> Alboraya, 10 | C5: =IFERROR(__xludf.DUMMYFUNCTION("""COMPUTED_VALUE"""),"Ventanas, Puerta Patio, Alicatado zaguán, Luminaria") -> Ventanas, Puerta Patio, Alicatado zaguán, Luminaria | D5: =IFERROR(__xludf.DUMMYFUNCTION("""COMPUTED_VALUE"""),46140.0) -> 46140 | F5: =IFERROR(__xludf.DUMMYFUNCTION("""COMPUTED_VALUE"""),"Ivan") -> Ivan
A6: =IFERROR(__xludf.DUMMYFUNCTION("""COMPUTED_VALUE"""),46144.83174925926) -> 46144.832 | B6: =IFERROR(__xludf.DUMMYFUNCTION("""COMPUTED_VALUE"""),"Arquitecto Alfaro, 25") -> Arquitecto Alfaro, 25 | C6: =IFERROR(__xludf.DUMMYFUNCTION("""COMPUTED_VALUE"""),"Pasaje") -> Pasaje | D6: =IFERROR(__xludf.DUMMYFUNCTION("""COMPUTED_VALUE"""),46144.0) -> 46144
A7: =IFERROR(__xludf.DUMMYFUNCTION("""COMPUTED_VALUE"""),46142.449749583335) -> 46142.45 | B7: =IFERROR(__xludf.DUMMYFUNCTION("""COMPUTED_VALUE"""),"Bellús, 1") -> Bellús, 1 | C7: =IFERROR(__xludf.DUMMYFUNCTION("""COMPUTED_VALUE"""),"Ventanas, Puerta Patio, Alicatado zaguán") -> Ventanas, Puerta Patio, Alicatado zaguán | D7: =IFERROR(__xludf.DUMMYFUNCTION("""COMPUTED_VALUE"""),46092.0) -> 46092 | F7: =IFERROR(__xludf.DUMMYFUNCTION("""COMPUTED_VALUE"""),"Ivan") -> Ivan
A8: =IFERROR(__xludf.DUMMYFUNCTION("""COMPUTED_VALUE"""),46142.39289282408) -> 46142.393 | B8: =IFERROR(__xludf.DUMMYFUNCTION("""COMPUTED_VALUE"""),"Bellús, 1") -> Bellús, 1 | C8: =IFERROR(__xludf.DUMMYFUNCTION("""COMPUTED_VALUE"""),"Ventanas, Puerta Patio, Alicatado zaguán") -> Ventanas, Puerta Patio, Alicatado zaguán | D8: =IFERROR(__xludf.DUMMYFUNCTION("""COMPUTED_VALUE"""),46140.0) -> 46140 | F8: =IFERROR(__xludf.DUMMYFUNCTION("""COMPUTED_VALUE"""),"Ivan ") -> Ivan
A9: =IFERROR(__xludf.DUMMYFUNCTION("""COMPUTED_VALUE"""),46142.39364744213) -> 46142.394 | B9: =IFERROR(__xludf.DUMMYFUNCTION("""COMPUTED_VALUE"""),"Daroca, 26") -> Daroca, 26 | C9: =IFERROR(__xludf.DUMMYFUNCTION("""COMPUTED_VALUE"""),"Ventanas, Puerta Patio, Terraza, Alicatado zaguán") -> Ventanas, Puerta Patio, Terraza, Alicatado zaguán | D9: =IFERROR(__xludf.DUMMYFUNCTION("""COMPUTED_VALUE"""),46140.0) -> 46140 | F9: =IFERROR(__xludf.DUMMYFUNCTION("""COMPUTED_VALUE"""),"Ivan") -> Ivan
A10: =IFERROR(__xludf.DUMMYFUNCTION("""COMPUTED_VALUE"""),46162.769890717595) -> 46162.77 | B10: =IFERROR(__xludf.DUMMYFUNCTION("""COMPUTED_VALUE"""),"FEV") -> FEV | C10: =IFERROR(__xludf.DUMMYFUNCTION("""COMPUTED_VALUE"""),"Cristales") -> Cristales | D10: =IFERROR(__xludf.DUMMYFUNCTION("""COMPUTED_VALUE"""),46162.0) -> 46162
A11: =IFERROR(__xludf.DUMMYFUNCTION("""COMPUTED_VALUE"""),46162.77086563657) -> 46162.771 | B11: =IFERROR(__xludf.DUMMYFUNCTION("""COMPUTED_VALUE"""),"FEV") -> FEV | C11: =IFERROR(__xludf.DUMMYFUNCTION("""COMPUTED_VALUE"""),"Ventanas") -> Ventanas | D11: =IFERROR(__xludf.DUMMYFUNCTION("""COMPUTED_VALUE"""),46162.0) -> 46162
A12: =IFERROR(__xludf.DUMMYFUNCTION("""COMPUTED_VALUE"""),46142.39423908565) -> 46142.394 | B12: =IFERROR(__xludf.DUMMYFUNCTION("""COMPUTED_VALUE"""),"Músico Cabanilles, 42") -> Músico Cabanilles, 42 | C12: =IFERROR(__xludf.DUMMYFUNCTION("""COMPUTED_VALUE"""),"Ventanas, Puerta Patio, Terraza, Alicatado zaguán") -> Ventanas, Puerta Patio, Terraza, Alicatado zaguán | D12: =IFERROR(__xludf.DUMMYFUNCTION("""COMPUTED_VALUE"""),46140.0) -> 46140 | F12: =IFERROR(__xludf.DUMMYFUNCTION("""COMPUTED_VALUE"""),"Ivan") -> Ivan
A13: =IFERROR(__xludf.DUMMYFUNCTION("""COMPUTED_VALUE"""),46142.39579765046) -> 46142.396 | B13: =IFERROR(__xludf.DUMMYFUNCTION("""COMPUTED_VALUE"""),"PDBF, 1") -> PDBF, 1 | C13: =IFERROR(__xludf.DUMMYFUNCTION("""COMPUTED_VALUE"""),"Ventanas, Puerta Patio, Terraza, Alicatado zaguán, Luminaria") -> Ventanas, Puerta Patio, Terraza, Alicatado zaguán, Luminaria | D13: =IFERROR(__xludf.DUMMYFUNCTION("""COMPUTED_VALUE"""),46140.0) -> 46140 | F13: =IFERROR(__xludf.DUMMYFUNCTION("""COMPUTED_VALUE"""),"Ivan") -> Ivan
A14: =IFERROR(__xludf.DUMMYFUNCTION("""COMPUTED_VALUE"""),46142.396089988426) -> 46142.396 | B14: =IFERROR(__xludf.DUMMYFUNCTION("""COMPUTED_VALUE"""),"PDBF, 2") -> PDBF, 2 | C14: =IFERROR(__xludf.DUMMYFUNCTION("""COMPUTED_VALUE"""),"Ventanas, Puerta Patio, Terraza, Alicatado zaguán") -> Ventanas, Puerta Patio, Terraza, Alicatado zaguán | D14: =IFERROR(__xludf.DUMMYFUNCTION("""COMPUTED_VALUE"""),46140.0) -> 46140 | F14: =IFERROR(__xludf.DUMMYFUNCTION("""COMPUTED_VALUE"""),"Ivan") -> Ivan
A15: =IFERROR(__xludf.DUMMYFUNCTION("""COMPUTED_VALUE"""),46145.44536541667) -> 46145.445 | B15: =IFERROR(__xludf.DUMMYFUNCTION("""COMPUTED_VALUE"""),"PDBF, 2") -> PDBF, 2 | C15: =IFERROR(__xludf.DUMMYFUNCTION("""COMPUTED_VALUE"""),"Ventanas, Puerta Patio") -> Ventanas, Puerta Patio | D15: =IFERROR(__xludf.DUMMYFUNCTION("""COMPUTED_VALUE"""),46145.0) -> 46145
A16: =IFERROR(__xludf.DUMMYFUNCTION("""COMPUTED_VALUE"""),46142.39323638889) -> 46142.393 | B16: =IFERROR(__xludf.DUMMYFUNCTION("""COMPUTED_VALUE"""),"Pintor Genaro Lahuerta, 45") -> Pintor Genaro Lahuerta, 45 | C16: =IFERROR(__xludf.DUMMYFUNCTION("""COMPUTED_VALUE"""),"Ventanas, Puerta Patio, Alicatado zaguán") -> Ventanas, Puerta Patio, Alicatado zaguán | D16: =IFERROR(__xludf.DUMMYFUNCTION("""COMPUTED_VALUE"""),46140.0) -> 46140 | F16: =IFERROR(__xludf.DUMMYFUNCTION("""COMPUTED_VALUE"""),"Ivan") -> Ivan
A17: =IFERROR(__xludf.DUMMYFUNCTION("""COMPUTED_VALUE"""),46142.39628811342) -> 46142.396 | B17: =IFERROR(__xludf.DUMMYFUNCTION("""COMPUTED_VALUE"""),"Plaza Dramaturgo Fausto Hernández Casajuana, 2") -> Plaza Dramaturgo Fausto Hernández Casajuana, 2 | C17: =IFERROR(__xludf.DUMMYFUNCTION("""COMPUTED_VALUE"""),"Puerta Patio") -> Puerta Patio | D17: =IFERROR(__xludf.DUMMYFUNCTION("""COMPUTED_VALUE"""),46140.0) -> 46140 | F17: =IFERROR(__xludf.DUMMYFUNCTION("""COMPUTED_VALUE"""),"Ivan") -> Ivan
A18: =IFERROR(__xludf.DUMMYFUNCTION("""COMPUTED_VALUE"""),46162.634519363426) -> 46162.635 | B18: =IFERROR(__xludf.DUMMYFUNCTION("""COMPUTED_VALUE"""),"VW Group Services") -> VW Group Services | C18: =IFERROR(__xludf.DUMMYFUNCTION("""COMPUTED_VALUE"""),"Ventanas") -> Ventanas | D18: =IFERROR(__xludf.DUMMYFUNCTION("""COMPUTED_VALUE"""),46162.0) -> 46162
